Workbook
Name Slicer_Category: #N/A
Name Slicer_PaymentMode: #N/A

Sheet Data Entry And Basic Formatting
A1: OrderID | B1: Date | C1: Customer | D1: City | E1: Product | F1: Category | G1: Quantity | H1: UnitPrice | I1: PaymentMode | J1: Salesperson
A2: 1001 | B2: 46235 | C2: Rahul | D2: Lucknow | E2: Laptop | F2: Electronics | G2: 2 | H2: 55000 | I2: UPI | J2: Amit
A3: 1002 | B3: 46235 | C3: Priya | D3: Kanpur | E3: Smartphone | F3: Electronics | G3: 3 | H3: 22000 | I3: Card | J3: Neha
A4: 1003 | B4: 46236 | C4: Ankit | D4: Delhi | E4: Keyboard | F4: Accessories | G4: 5 | H4: 1200 | I4: Cash | J4: Rohit
A5: 1004 | B5: 46236 | C5: Sneha | D5: Lucknow | E5: Mouse | F5: Accessories | G5: 4 | H5: 800 | I5: UPI | J5: Amit
A6: 1005 | B6: 46237 | C6: Vivek | D6: Jaipur | E6: Headphones | F6: Accessories | G6: 2 | H6: 2500 | I6: Card | J6: Priya
A7: 1006 | B7: 46237 | C7: Pooja | D7: Delhi | E7: Monitor | F7: Electronics | G7: 2 | H7: 15000 | I7: UPI | J7: Neha
A8: 1007 | B8: 46238 | C8: Arjun | D8: Kanpur | E8: Laptop | F8: Electronics | G8: 1 | H8: 62000 | I8: Card | J8: Rohit
A9: 1008 | B9: 46238 | C9: Kavita | D9: Lucknow | E9: Printer | F9: Electronics | G9: 2 | H9: 9500 | I9: Cash | J9: Amit
A10: 1009 | B10: 46239 | C10: Riya | D10: Agra | E10: headphones | F10: Electronics | G10: 2 | H10: 18000 | I10: UPI | J10: Priya
A11: 1010 | B11: 46239 | C11: Mohit | D11: Jaipur | E11: Keyboard | F11: Accessories | G11: 3 | H11: 1500 | I11: Card | J11: Neha
A12: 1011 | B12: 46240 | C12: Nisha | D12: Lucknow | E12: Mouse | F12: Accessories | G12: 6 | H12: 700 | I12: UPI | J12: Rohit
A13: 1012 | B13: 46240 | C13: Karan | D13: Delhi | E13: Laptop | F13: Electronics | G13: 1 | H13: 58000 | I13: Card | J13: Amit
... A51: 1050 | B51: 46259 | C51: Sonam | D51: Jaipur | E51: Headphones | F51: Accessories | G51: 4 | H51: 2700 | I51: Cash | J51: Neha

Sheet Basic Formula
A1: OrderID | B1: Date | C1: Customer | D1: City | E1: Product | F1: Category | G1: Quantity | H1: UnitPrice | I1: PaymentMode | J1: Salesperson | K1: Sales
A2: 1001 | B2: 46235 | C2: Rahul | D2: Lucknow | E2: Laptop | F2: Electronics | G2: 2 | H2: 55000 | I2: UPI | J2: Amit | K2: =G2*H2 -> 110000
A3: 1002 | B3: 46235 | C3: Priya | D3: Kanpur | E3: Smartphone | F3: Electronics | G3: 3 | H3: 22000 | I3: Card | J3: Neha | K3: =G3*H3 -> 66000
A4: 1003 | B4: 46236 | C4: Ankit | D4: Delhi | E4: Keyboard | F4: Accessories | G4: 5 | H4: 1200 | I4: Cash | J4: Rohit | K4: =G4*H4 -> 6000 | M4: Max Sales | N4: =MAX(K2:K51) -> 120000
A5: 1004 | B5: 46236 | C5: Sneha | D5: Lucknow | E5: Mouse | F5: Accessories | G5: 4 | H5: 800 | I5: UPI | J5: Amit | K5: =G5*H5 -> 3200 | M5: Min Sales | N5: =MIN(K2:K51) -> 2850
A6: 1005 | B6: 46237 | C6: Vivek | D6: Jaipur | E6: Headphones | F6: Accessories | G6: 2 | H6: 2500 | I6: Card | J6: Priya | K6: =G6*H6 -> 5000 | M6: Avg Sales | N6: =AVERAGE(K2:K51) -> 31568
A7: 1006 | B7: 46237 | C7: Pooja | D7: Delhi | E7: Monitor | F7: Electronics | G7: 2 | H7: 15000 | I7: UPI | J7: Neha | K7: =G7*H7 -> 30000 | M7: Total Sales | N7: =SUM(K2:K54) -> 1578400
A8: 1007 | B8: 46238 | C8: Arjun | D8: Kanpur | E8: Laptop | F8: Electronics | G8: 1 | H8: 62000 | I8: Card | J8: Rohit | K8: =G8*H8 -> 62000
A9: 1008 | B9: 46238 | C9: Kavita | D9: Lucknow | E9: Printer | F9: Electronics | G9: 2 | H9: 9500 | I9: Cash | J9: Amit | K9: =G9*H9 -> 19000
A10: 1009 | B10: 46239 | C10: Riya | D10: Agra | E10: headphones | F10: Electronics | G10: 2 | H10: 18000 | I10: UPI | J10: Priya | K10: =G10*H10 -> 36000
A11: 1010 | B11: 46239 | C11: Mohit | D11: Jaipur | E11: Keyboard | F11: Accessories | G11: 3 | H11: 1500 | I11: Card | J11: Neha | K11: =G11*H11 -> 4500
A12: 1011 | B12: 46240 | C12: Nisha | D12: Lucknow | E12: Mouse | F12: Accessories | G12: 6 | H12: 700 | I12: UPI | J12: Rohit | K12: =G12*H12 -> 4200
A13: 1012 | B13: 46240 | C13: Karan | D13: Delhi | E13: Laptop | F13: Electronics | G13: 1 | H13: 58000 | I13: Card | J13: Amit | K13: =G13*H13 -> 58000
A14: 1013 | B14: 46241 | C14: Simran | D14: Kanpur | E14: Monitor | F14: Electronics | G14: 3 | H14: 13500 | I14: UPI | J14: Priya | K14: =G14*H14 -> 40500
A15: 1014 | B15: 46241 | C15: Aditya | D15: Agra | E15: Headphones | F15: Accessories | G15: 4 | H15: 2200 | I15: Cash | J15: Neha | K15: =G15*H15 -> 8800
A16: 1015 | B16: 46242 | C16: Meena | D16: Jaipur | E16: Printer | F16: Electronics | G16: 1 | H16: 11000 | I16: Card | J16: Rohit | K16: =G16*H16 -> 11000
A17: 1016 | B17: 46242 | C17: Aman | D17: Lucknow | E17: Smartphone | F17: Electronics | G17: 3 | H17: 25000 | I17: UPI | J17: Amit | K17: =G17*H17 -> 75000
A18: 1017 | B18: 46243 | C18: Shreya | D18: Delhi | E18: Keyboard | F18: Accessories | G18: 5 | H18: 1300 | I18: Cash | J18: Priya | K18: =G18*H18 -> 6500
A19: 1018 | B19: 46243 | C19: Saurabh | D19: Kanpur | E19: Mouse | F19: Accessories | G19: 8 | H19: 650 | I19: Card | J19: Neha | K19: =G19*H19 -> 5200
... A51: 1050 | B51: 46259 | C51: Sonam | D51: Jaipur | E51: Headphones | F51: Accessories | G51: 4 | H51: 2700 | I51: Cash | J51: Neha | K51: =G51*H51 -> 10800

Sheet Conditional Formatting
A1: OrderID | B1: Date | C1: Customer | D1: City | E1: Product | F1: Category | G1: Quantity | H1: UnitPrice | I1: PaymentMode | J1: Salesperson
A2: 1001 | B2: 46235 | C2: Rahul | D2: Lucknow | E2: Laptop | F2: Electronics | G2: 2 | H2: 55000 | I2: UPI | J2: Amit
A3: 1002 | B3: 46235 | C3: Priya | D3: Kanpur | E3: Smartphone | F3: Electronics | G3: 3 | H3: 22000 | I3: Card | J3: Neha
A4: 1003 | B4: 46236 | C4: Ankit | D4: Delhi | E4: Keyboard | F4: Accessories | G4: 5 | H4: 1200 | I4: Cash | J4: Rohit
A5: 1004 | B5: 46236 | C5: Sneha | D5: Lucknow | E5: Mouse | F5: Accessories | G5: 4 | H5: 800 | I5: UPI | J5: Amit
A6: 1005 | B6: 46237 | C6: Vivek | D6: Jaipur | E6: Headphones | F6: Accessories | G6: 2 | H6: 2500 | I6: Card | J6: Priya
A7: 1006 | B7: 46237 | C7: Pooja | D7: Delhi | E7: Monitor | F7: Electronics | G7: 2 | H7: 15000 | I7: UPI | J7: Neha
A8: 1007 | B8: 46238 | C8: Arjun | D8: Kanpur | E8: Laptop | F8: Electronics | G8: 1 | H8: 62000 | I8: Card | J8: Rohit
A9: 1008 | B9: 46238 | C9: Kavita | D9: Lucknow | E9: Printer | F9: Electronics | G9: 2 | H9: 9500 | I9: Cash | J9: Amit
A10: 1009 | B10: 46239 | C10: Riya | D10: Agra | E10: headphones | F10: Electronics | G10: 2 | H10: 18000 | I10: UPI | J10: Priya
A11: 1010 | B11: 46239 | C11: Mohit | D11: Jaipur | E11: Keyboard | F11: Accessories | G11: 3 | H11: 1500 | I11: Card | J11: Neha
A12: 1011 | B12: 46240 | C12: Nisha | D12: Lucknow | E12: Mouse | F12: Accessories | G12: 6 | H12: 700 | I12: UPI | J12: Rohit
A13: 1012 | B13: 46240 | C13: Karan | D13: Delhi | E13: Laptop | F13: Electronics | G13: 1 | H13: 58000 | I13: Card | J13: Amit
... A51: 1050 | B51: 46259 | C51: Sonam | D51: Jaipur | E51: Headphones | F51: Accessories | G51: 4 | H51: 2700 | I51: Cash | J51: Neha

Sheet Sorting 
A6: Soting By Name (From A to Z) | L6: Soting By Name (From Z to A)
A7: OrderID | B7: Date | C7: Customer | D7: City | E7: Product | F7: Category | G7: Quantity | H7: UnitPrice | I7: PaymentMode | J7: Salesperson | L7: OrderID | M7: Date | N7: Customer | O7: City | P7: Product | Q7: Category | R7: Quantity | S7: UnitPrice | T7: PaymentMode | U7: Salesperson
A8: 1014 | B8: 46241 | C8: Aditya | D8: Agra | E8: Headphones | F8: Accessories | G8: 4 | H8: 2200 | I8: Cash | J8: Neha | L8: 1005 | M8: 46237 | N8: Vivek | O8: Jaipur | P8: Headphones | Q8: Accessories | R8: 2 | S8: 2500 | T8: Card | U8: Priya
A9: 1003 | B9: 46236 | C9: Ankit | D9: Delhi | E9: Keyboard | F9: Accessories | G9: 5 | H9: 1200 | I9: Cash | J9: Rohit | L9: 1004 | M9: 46236 | N9: Sneha | O9: Lucknow | P9: Mouse | Q9: Accessories | R9: 4 | S9: 800 | T9: UPI | U9: Amit
A10: 1007 | B10: 46238 | C10: Arjun | D10: Kanpur | E10: Laptop | F10: Electronics | G10: 1 | H10: 62000 | I10: Card | J10: Rohit | L10: 1013 | M10: 46241 | N10: Simran | O10: Kanpur | P10: Monitor | Q10: Electronics | R10: 3 | S10: 13500 | T10: UPI | U10: Priya
A11: 1012 | B11: 46240 | C11: Karan | D11: Delhi | E11: Laptop | F11: Electronics | G11: 1 | H11: 58000 | I11: Card | J11: Amit | L11: 1009 | M11: 46239 | N11: Riya | O11: Agra | P11: headphones | Q11: Electronics | R11: 2 | S11: 18000 | T11: UPI | U11: Priya
A12: 1008 | B12: 46238 | C12: Kavita | D12: Lucknow | E12: Printer | F12: Electronics | G12: 2 | H12: 9500 | I12: Cash | J12: Amit | L12: 1001 | M12: 46235 | N12: Rahul | O12: Lucknow | P12: Laptop | Q12: Electronics | R12: 2 | S12: 55000 | T12: UPI | U12: Amit
A13: 1015 | B13: 46242 | C13: Meena | D13: Jaipur | E13: Printer | F13: Electronics | G13: 1 | H13: 11000 | I13: Card | J13: Rohit | L13: 1002 | M13: 46235 | N13: Priya | O13: Kanpur | P13: Smartphone | Q13: Electronics | R13: 3 | S13: 22000 | T13: Card | U13: Neha
A14: 1010 | B14: 46239 | C14: Mohit | D14: Jaipur | E14: Keyboard | F14: Accessories | G14: 3 | H14: 1500 | I14: Card | J14: Neha | L14: 1006 | M14: 46237 | N14: Pooja | O14: Delhi | P14: Monitor | Q14: Electronics | R14: 2 | S14: 15000 | T14: UPI | U14: Neha
A15: 1011 | B15: 46240 | C15: Nisha | D15: Lucknow | E15: Mouse | F15: Accessories | G15: 6 | H15: 700 | I15: UPI | J15: Rohit | L15: 1011 | M15: 46240 | N15: Nisha | O15: Lucknow | P15: Mouse | Q15: Accessories | R15: 6 | S15: 700 | T15: UPI | U15: Rohit
A16: 1006 | B16: 46237 | C16: Pooja | D16: Delhi | E16: Monitor | F16: Electronics | G16: 2 | H16: 15000 | I16: UPI | J16: Neha | L16: 1010 | M16: 46239 | N16: Mohit | O16: Jaipur | P16: Keyboard | Q16: Accessories | R16: 3 | S16: 1500 | T16: Card | U16: Neha
A17: 1002 | B17: 46235 | C17: Priya | D17: Kanpur | E17: Smartphone | F17: Electronics | G17: 3 | H17: 22000 | I17: Card | J17: Neha | L17: 1015 | M17: 46242 | N17: Meena | O17: Jaipur | P17: Printer | Q17: Electronics | R17: 1 | S17: 11000 | T17: Card | U17: Rohit
A18: 1001 | B18: 46235 | C18: Rahul | D18: Lucknow | E18: Laptop | F18: Electronics | G18: 2 | H18: 55000 | I18: UPI | J18: Amit | L18: 1008 | M18: 46238 | N18: Kavita | O18: Lucknow | P18: Printer | Q18: Electronics | R18: 2 | S18: 9500 | T18: Cash | U18: Amit
A19: 1009 | B19: 46239 | C19: Riya | D19: Agra | E19: headphones | F19: Electronics | G19: 2 | H19: 18000 | I19: UPI | J19: Priya | L19: 1012 | M19: 46240 | N19: Karan | O19: Delhi | P19: Laptop | Q19: Electronics | R19: 1 | S19: 58000 | T19: Card | U19: Amit
... A22: 1005 | B22: 46237 | C22: Vivek | D22: Jaipur | E22: Headphones | F22: Accessories | G22: 2 | H22: 2500 | I22: Card | J22: Priya | L22: 1014 | M22: 46241 | N22: Aditya | O22: Agra | P22: Headphones | Q22: Accessories | R22: 4 | S22: 2200 | T22: Cash | U22: Neha
B25: Multi -Level Sorting
B26: OrderID | C26: Date | D26: Customer | E26: City | F26: Product | G26: Category | H26: Quantity | I26: UnitPrice | J26: PaymentMode | K26: Salesperson
B27: 1014 | C27: 46241 | D27: Aditya | E27: Agra | F27: Headphones | G27: Accessories | H27: 4 | I27: 2200 | J27: Cash | K27: Neha
B28: 1003 | C28: 46236 | D28: Ankit | E28: Delhi | F28: Keyboard | G28: Accessories | H28: 5 | I28: 1200 | J28: Cash | K28: Rohit
B29: 1007 | C29: 46238 | D29: Arjun | E29: Kanpur | F29: Laptop | G29: Electronics | H29: 1 | I29: 62000 | J29: Card | K29: Rohit
B30: 1012 | C30: 46240 | D30: Karan | E30: Delhi | F30: Laptop | G30: Electronics | H30: 1 | I30: 58000 | J30: Card | K30: Amit
B31: 1008 | C31: 46238 | D31: Kavita | E31: Lucknow | F31: Printer | G31: Electronics | H31: 2 | I31: 9500 | J31: Cash | K31: Amit
B32: 1015 | C32: 46242 | D32: Meena | E32: Jaipur | F32: Printer | G32: Electronics | H32: 1 | I32: 11000 | J32: Card | K32: Rohit
B33: 1010 | C33: 46239 | D33: Mohit | E33: Jaipur | F33: Keyboard | G33: Accessories | H33: 3 | I33: 1500 | J33: Card | K33: Neha
B34: 1011 | C34: 46240 | D34: Nisha | E34: Lucknow | F34: Mouse | G34: Accessories | H34: 6 | I34: 700 | J34: UPI | K34: Rohit
B35: 1006 | C35: 46237 | D35: Pooja | E35: Delhi | F35: Monitor | G35: Electronics | H35: 2 | I35: 15000 | J35: UPI | K35: Neha
B36: 1002 | C36: 46235 | D36: Priya | E36: Kanpur | F36: Smartphone | G36: Electronics | H36: 3 | I36: 22000 | J36: Card | K36: Neha
B37: 1001 | C37: 46235 | D37: Rahul | E37: Lucknow | F37: Laptop | G37: Electronics | H37: 2 | I37: 55000 | J37: UPI | K37: Amit
B38: 1009 | C38: 46239 | D38: Riya | E38: Agra | F38: headphones | G38: Electronics | H38: 2 | I38: 18000 | J38: UPI | K38: Priya
... B41: 1005 | C41: 46237 | D41: Vivek | E41: Jaipur | F41: Headphones | G41: Accessories | H41: 2 | I41: 2500 | J41: Card | K41: Priya

Sheet Filter
A1: Filter by Category
A2: OrderID | B2: Date | C2: Customer | D2: City | E2: Product | F2: Category | G2: Quantity | H2: UnitPrice | I2: PaymentMode | J2: Salesperson
A3: 1001 | B3: 46235 | C3: Rahul | D3: Lucknow | E3: Laptop | F3: Electronics | G3: 2 | H3: 55000 | I3: UPI | J3: Amit
A4: 1002 | B4: 46235 | C4: Priya | D4: Kanpur | E4: Smartphone | F4: Electronics | G4: 3 | H4: 22000 | I4: Card | J4: Neha
A5: 1003 | B5: 46236 | C5: Ankit | D5: Delhi | E5: Keyboard | F5: Accessories | G5: 5 | H5: 1200 | I5: Cash | J5: Rohit
A6: 1004 | B6: 46236 | C6: Sneha | D6: Lucknow | E6: Mouse | F6: Accessories | G6: 4 | H6: 800 | I6: UPI | J6: Amit
A7: 1005 | B7: 46237 | C7: Vivek | D7: Jaipur | E7: Headphones | F7: Accessories | G7: 2 | H7: 2500 | I7: Card | J7: Priya
A8: 1006 | B8: 46237 | C8: Pooja | D8: Delhi | E8: Monitor | F8: Electronics | G8: 2 | H8: 15000 | I8: UPI | J8: Neha
A9: 1007 | B9: 46238 | C9: Arjun | D9: Kanpur | E9: Laptop | F9: Electronics | G9: 1 | H9: 62000 | I9: Card | J9: Rohit
A10: 1008 | B10: 46238 | C10: Kavita | D10: Lucknow | E10: Printer | F10: Electronics | G10: 2 | H10: 9500 | I10: Cash | J10: Amit
A11: 1009 | B11: 46239 | C11: Riya | D11: Agra | E11: headphones | F11: Electronics | G11: 2 | H11: 18000 | I11: UPI | J11: Priya
A12: 1010 | B12: 46239 | C12: Mohit | D12: Jaipur | E12: Keyboard | F12: Accessories | G12: 3 | H12: 1500 | I12: Card | J12: Neha
A13: 1011 | B13: 46240 | C13: Nisha | D13: Lucknow | E13: Mouse | F13: Accessories | G13: 6 | H13: 700 | I13: UPI | J13: Rohit
A14: 1012 | B14: 46240 | C14: Karan | D14: Delhi | E14: Laptop | F14: Electronics | G14: 1 | H14: 58000 | I14: Card | J14: Amit
... A52: 1050 | B52: 46259 | C52: Sonam | D52: Jaipur | E52: Headphones | F52: Accessories | G52: 4 | H52: 2700 | I52: Cash | J52: Neha

Sheet Table Creation
A1: Table Creation
A2: OrderID | B2: Date | C2: Customer | D2: City | E2: Product | F2: Category | G2: Quantity | H2: UnitPrice | I2: PaymentMode | J2: Salesperson | K2: Total Sal
A3: 1001 | B3: 46235 | C3: Rahul | D3: Lucknow | E3: Laptop | F3: Electronics | G3: 2 | H3: 55000 | I3: UPI | J3: Amit | K3: =Table2[[#This Row],[Quantity]]*Table2[[#This Row],[UnitPrice]] -> 110000
A4: 1002 | B4: 46235 | C4: Priya | D4: Kanpur | E4: Smartphone | F4: Electronics | G4: 3 | H4: 22000 | I4: Card | J4: Neha | K4: =Table2[[#This Row],[Quantity]]*Table2[[#This Row],[UnitPrice]] -> 66000
A5: 1003 | B5: 46236 | C5: Ankit | D5: Delhi | E5: Keyboard | F5: Accessories | G5: 5 | H5: 1200 | I5: Cash | J5: Rohit
A6: 1004 | B6: 46236 | C6: Sneha | D6: Lucknow | E6: Mouse | F6: Accessories | G6: 4 | H6: 800 | I6: UPI | J6: Amit
A7: 1005 | B7: 46237 | C7: Vivek | D7: Jaipur | E7: Headphones | F7: Accessories | G7: 2 | H7: 2500 | I7: Card | J7: Priya
A8: 1006 | B8: 46237 | C8: Pooja | D8: Delhi | E8: Monitor | F8: Electronics | G8: 2 | H8: 15000 | I8: UPI | J8: Neha | K8: =Table2[[#This Row],[Quantity]]*Table2[[#This Row],[UnitPrice]] -> 30000
A9: 1007 | B9: 46238 | C9: Arjun | D9: Kanpur | E9: Laptop | F9: Electronics | G9: 1 | H9: 62000 | I9: Card | J9: Rohit | K9: =Table2[[#This Row],[Quantity]]*Table2[[#This Row],[UnitPrice]] -> 62000
A10: 1008 | B10: 46238 | C10: Kavita | D10: Lucknow | E10: Printer | F10: Electronics | G10: 2 | H10: 9500 | I10: Cash | J10: Amit
A11: 1009 | B11: 46239 | C11: Riya | D11: Agra | E11: headphones | F11: Electronics | G11: 2 | H11: 18000 | I11: UPI | J11: Priya | K11: =Table2[[#This Row],[Quantity]]*Table2[[#This Row],[UnitPrice]] -> 36000
A12: 1010 | B12: 46239 | C12: Mohit | D12: Jaipur | E12: Keyboard | F12: Accessories | G12: 3 | H12: 1500 | I12: Card | J12: Neha
A13: 1011 | B13: 46240 | C13: Nisha | D13: Lucknow | E13: Mouse | F13: Accessories | G13: 6 | H13: 700 | I13: UPI | J13: Rohit
A14: 1012 | B14: 46240 | C14: Karan | D14: Delhi | E14: Laptop | F14: Electronics | G14: 1 | H14: 58000 | I14: Card | J14: Amit | K14: =Table2[[#This Row],[Quantity]]*Table2[[#This Row],[UnitPrice]] -> 58000
A15: 1013 | B15: 46241 | C15: Simran | D15: Kanpur | E15: Monitor | F15: Electronics | G15: 3 | H15: 13500 | I15: UPI | J15: Priya | K15: =Table2[[#This Row],[Quantity]]*Table2[[#This Row],[UnitPrice]] -> 40500
A16: 1014 | B16: 46241 | C16: Aditya | D16: Agra | E16: Headphones | F16: Accessories | G16: 4 | H16: 2200 | I16: Cash | J16: Neha
A17: 1015 | B17: 46242 | C17: Meena | D17: Jaipur | E17: Printer | F17: Electronics | G17: 1 | H17: 11000 | I17: Card | J17: Rohit | K17: =Table2[[#This Row],[Quantity]]*Table2[[#This Row],[UnitPrice]] -> 11000
A18: 1016 | B18: 46242 | C18: Aman | D18: agra | E18: Smartphone | F18: Electronics | G18: 3 | H18: 25000 | I18: UPI | J18: Amit | K18: =Table2[[#This Row],[Quantity]]*Table2[[#This Row],[UnitPrice]] -> 75000
A19: 1017 | B19: 46243 | C19: Shreya | D19: Delhi | E19: Keyboard | F19: Accessories | G19: 5 | H19: 1300 | I19: Cash | J19: Priya
A20: 1018 | B20: 46243 | C20: Saurabh | D20: Kanpur | E20: Mouse | F20: Accessories | G20: 8 | H20: 650 | I20: Card | J20: Neha
A21: 1019 | B21: 46244 | C21: Neha | D21: Agra | E21: Laptop | F21: Electronics | G21: 2 | H21: 60000 | I21: UPI | J21: Rohit | K21: =Table2[[#This Row],[Quantity]]*Table2[[#This Row],[UnitPrice]] -> 120000
A22: 1020 | B22: 46244 | C22: Raj | D22: Jaipur | E22: Monitor | F22: Electronics | G22: 1 | H22: 16000 | I22: Card | J22: Amit | K22: =Table2[[#This Row],[Quantity]]*Table2[[#This Row],[UnitPrice]] -> 16000
A23: 1021 | B23: 46245 | C23: Tanya | D23: Lucknow | E23: Printer | F23: Electronics | G23: 2 | H23: 9000 | I23: UPI | J23: Priya | K23: =Table2[[#This Row],[Quantity]]*Table2[[#This Row],[UnitPrice]] -> 18000
A24: 1022 | B24: 46245 | C24: Deepak | D24: Delhi | E24: Headphones | F24: Accessories | G24: 3 | H24: 2800 | I24: Cash | J24: Neha
A25: 1023 | B25: 46246 | C25: Aarti | D25: Kanpur | E25: Smartphone | F25: Electronics | G25: 2 | H25: 21000 | I25: Card | J25: Rohit | K25: =Table2[[#This Row],[Quantity]]*Table2[[#This Row],[UnitPrice]] -> 42000
A26: 1024 | B26: 46246 | C26: Manish | D26: Agra | E26: Keyboard | F26: Accessories | G26: 4 | H26: 1400 | I26: UPI | J26: Amit
A27: 1025 | B27: 46247 | C27: Jyoti | D27: Jaipur | E27: Mouse | F27: Accessories | G27: 5 | H27: 750 | I27: Cash | J27: Priya
A28: 1026 | B28: 46247 | C28: Rakesh | D28: Lucknow | E28: Laptop | F28: Electronics | G28: 1 | H28: 65000 | I28: Card | J28: Neha | K28: =Table2[[#This Row],[Quantity]]*Table2[[#This Row],[UnitPrice]] -> 65000
A29: 1027 | B29: 46248 | C29: Pankaj | D29: Delhi | E29: Monitor | F29: Electronics | G29: 2 | H29: 14500 | I29: UPI | J29: Rohit | K29: =Table2[[#This Row],[Quantity]]*Table2[[#This Row],[UnitPrice]] -> 29000
A30: 1028 | B30: 46248 | C30: Komal | D30: Kanpur | E30: Printer | F30: Electronics | G30: 3 | H30: 8500 | I30: Card | J30: Amit | K30: =Table2[[#This Row],[Quantity]]*Table2[[#This Row],[UnitPrice]] -> 25500
A31: 1029 | B31: 46249 | C31: Varun | D31: Agra | E31: Smartphone | F31: Electronics | G31: 1 | H31: 23000 | I31: Cash | J31: Priya
A32: 1030 | B32: 46249 | C32: Anjali | D32: Jaipur | E32: Headphones | F32: Accessories | G32: 2 | H32: 3000 | I32: UPI | J32: Neha
A33: 1031 | B33: 46250 | C33: Harish | D33: Lucknow | E33: Keyboard | F33: Accessories | G33: 7 | H33: 1100 | I33: Card | J33: Rohit
A34: 1032 | B34: 46250 | C34: Preeti | D34: Delhi | E34: Mouse | F34: Accessories | G34: 4 | H34: 900 | I34: UPI | J34: Amit
A35: 1033 | B35: 46251 | C35: Naveen | D35: Kanpur | E35: Laptop | F35: Electronics | G35: 2 | H35: 57000 | I35: Card | J35: Priya | K35: =Table2[[#This Row],[Quantity]]*Table2[[#This Row],[UnitPrice]] -> 114000
A36: 1034 | B36: 46251 | C36: Sakshi | D36: Agra | E36: Monitor | F36: Electronics | G36: 1 | H36: 15500 | I36: Cash | J36: Neha
A37: 1035 | B37: 46252 | C37: Yash | D37: Jaipur | E37: Printer | F37: Electronics | G37: 2 | H37: 10000 | I37: UPI | J37: Rohit | K37: =Table2[[#This Row],[Quantity]]*Table2[[#This Row],[UnitPrice]] -> 20000
A38: 1036 | B38: 46252 | C38: Isha | D38: Lucknow | E38: Smartphone | F38: Electronics | G38: 4 | H38: 19500 | I38: Card | J38: Amit | K38: =Table2[[#This Row],[Quantity]]*Table2[[#This Row],[UnitPrice]] -> 78000
A39: 1037 | B39: 46253 | C39: Sameer | D39: Delhi | E39: Keyboard | F39: Accessories | G39: 3 | H39: 1600 | I39: UPI | J39: Priya
A40: 1038 | B40: 46253 | C40: Divya | D40: Kanpur | E40: Mouse | F40: Accessories | G40: 6 | H40: 850 | I40: Cash | J40: Neha
...

Sheet Logical formula
A1: Logical Formula ( IF , IFS , SumIF,AverageIF)
A2: OrderID | B2: Date | C2: Customer | D2: City | E2: Product | F2: Category | G2: Quantity | H2: UnitPrice | I2: PaymentMode | J2: Salesperson | K2: Sales | L2: IFS
A3: 1001 | B3: 46235 | C3: Rahul | D3: Lucknow | E3: Laptop | F3: Electronics | G3: 2 | H3: 55000 | I3: UPI | J3: Amit | K3: =G3*H3 -> 110000 | L3: {=_xlfn.IFS(K3>=100000,"Great Sale",K3>=50000,"Good Sale",K3>=30,"Avg Sale",K3<=10000,"Poor Sale")} -> Great Sale | N3: SumIF, AverageIF
A4: 1002 | B4: 46235 | C4: Priya | D4: Kanpur | E4: Smartphone | F4: Electronics | G4: 3 | H4: 22000 | I4: Card | J4: Neha | K4: =G4*H4 -> 66000 | L4: {=_xlfn.IFS(K4>=100000,"Great Sale",K4>=50000,"Good Sale",K4>=30,"Avg Sale",K4<=10000,"Poor Sale")} -> Good Sale | N4: Customer Name TOTAL SALES | O4: Total Sale | P4: Avg Sale
A5: 1003 | B5: 46236 | C5: Ankit | D5: Delhi | E5: Keyboard | F5: Accessories | G5: 5 | H5: 1200 | I5: Cash | J5: Rohit | K5: =G5*H5 -> 6000 | L5: {=_xlfn.IFS(K5>=100000,"Great Sale",K5>=50000,"Good Sale",K5>=30,"Avg Sale",K5<=10000,"Poor Sale")} -> Avg Sale | N5: Rahul | O5: =SUMIF($C$3:$C$52,$N5,$K$3:$K$53) -> 261500 | P5: =AVERAGEIF($C$3:$C$52,N5,$K$3:$K$53) -> 52300
A6: 1004 | B6: 46236 | C6: Sneha | D6: Lucknow | E6: Mouse | F6: Accessories | G6: 4 | H6: 800 | I6: UPI | J6: Amit | K6: =G6*H6 -> 3200 | L6: {=_xlfn.IFS(K6>=100000,"Great Sale",K6>=50000,"Good Sale",K6>=30,"Avg Sale",K6<=10000,"Poor Sale")} -> Avg Sale | N6: Priya | O6: =SUMIF($C$3:$C$52,$N6,$K$3:$K$53) -> 66000 | P6: =AVERAGEIF($C$3:$C$52,N6,$K$3:$K$53) -> 66000
A7: 1005 | B7: 46237 | C7: Vivek | D7: Jaipur | E7: Headphones | F7: Accessories | G7: 2 | H7: 2500 | I7: Card | J7: Priya | K7: =G7*H7 -> 5000 | L7: {=_xlfn.IFS(K7>=100000,"Great Sale",K7>=50000,"Good Sale",K7>=30,"Avg Sale",K7<=10000,"Poor Sale")} -> Avg Sale | N7: Ankit | O7: =SUMIF($C$3:$C$52,$N7,$K$3:$K$53) -> 10500 | P7: =AVERAGEIF($C$3:$C$52,N7,$K$3:$K$53) -> 5250
A8: 1006 | B8: 46237 | C8: Pooja | D8: Delhi | E8: Monitor | F8: Electronics | G8: 2 | H8: 15000 | I8: UPI | J8: Neha | K8: =G8*H8 -> 30000 | L8: {=_xlfn.IFS(K8>=100000,"Great Sale",K8>=50000,"Good Sale",K8>=30,"Avg Sale",K8<=10000,"Poor Sale")} -> Avg Sale | N8: Sneha | O8: =SUMIF($C$3:$C$52,$N8,$K$3:$K$53) -> 3200 | P8: =AVERAGEIF($C$3:$C$52,N8,$K$3:$K$53) -> 3200
A9: 1007 | B9: 46238 | C9: Kavita | D9: Kanpur | E9: Laptop | F9: Electronics | G9: 1 | H9: 62000 | I9: Card | J9: Rohit | K9: =G9*H9 -> 62000 | L9: {=_xlfn.IFS(K9>=100000,"Great Sale",K9>=50000,"Good Sale",K9>=30,"Avg Sale",K9<=10000,"Poor Sale")} -> Good Sale | N9: Vivek | O9: =SUMIF($C$3:$C$52,$N9,$K$3:$K$53) -> 14500 | P9: =AVERAGEIF($C$3:$C$52,N9,$K$3:$K$53) -> 7250
A10: 1008 | B10: 46238 | C10: Kavita | D10: Lucknow | E10: Printer | F10: Electronics | G10: 2 | H10: 9500 | I10: Cash | J10: Amit | K10: =G10*H10 -> 19000 | L10: {=_xlfn.IFS(K10>=100000,"Great Sale",K10>=50000,"Good Sale",K10>=30,"Avg Sale",K10<=10000,"Poor Sale")} -> Avg Sale | N10: Pooja | O10: =SUMIF($C$3:$C$52,$N10,$K$3:$K$53) -> 30000 | P10: =AVERAGEIF($C$3:$C$52,N10,$K$3:$K$53) -> 30000
A11: 1009 | B11: 46239 | C11: Riya | D11: Agra | E11: headphones | F11: Electronics | G11: 2 | H11: 18000 | I11: UPI | J11: Priya | K11: =G11*H11 -> 36000 | L11: {=_xlfn.IFS(K11>=100000,"Great Sale",K11>=50000,"Good Sale",K11>=30,"Avg Sale",K11<=10000,"Poor Sale")} -> Avg Sale | N11: Kavita | O11: =SUMIF($C$3:$C$52,$N11,$K$3:$K$53) -> 199000 | P11: =AVERAGEIF($C$3:$C$52,N11,$K$3:$K$53) -> 66333.333
A12: 1010 | B12: 46239 | C12: Ankit | D12: Jaipur | E12: Keyboard | F12: Accessories | G12: 3 | H12: 1500 | I12: Card | J12: Neha | K12: =G12*H12 -> 4500 | L12: {=_xlfn.IFS(K12>=100000,"Great Sale",K12>=50000,"Good Sale",K12>=30,"Avg Sale",K12<=10000,"Poor Sale")} -> Avg Sale | N12: Riya | O12: =SUMIF($C$3:$C$52,$N12,$K$3:$K$53) -> 36000 | P12: =AVERAGEIF($C$3:$C$52,N12,$K$3:$K$53) -> 36000
A13: 1011 | B13: 46240 | C13: Nisha | D13: Lucknow | E13: Mouse | F13: Accessories | G13: 6 | H13: 700 | I13: UPI | J13: Rohit | K13: =G13*H13 -> 4200 | L13: {=_xlfn.IFS(K13>=100000,"Great Sale",K13>=50000,"Good Sale",K13>=30,"Avg Sale",K13<=10000,"Poor Sale")} -> Avg Sale | N13: Nisha | O13: =SUMIF($C$3:$C$52,$N13,$K$3:$K$53) -> 4200 | P13: =AVERAGEIF($C$3:$C$52,N13,$K$3:$K$53) -> 4200
A14: 1012 | B14: 46240 | C14: Karan | D14: Delhi | E14: Laptop | F14: Electronics | G14: 1 | H14: 58000 | I14: Card | J14: Amit | K14: =G14*H14 -> 58000 | L14: {=_xlfn.IFS(K14>=100000,"Great Sale",K14>=50000,"Good Sale",K14>=30,"Avg Sale",K14<=10000,"Poor Sale")} -> Good Sale | N14: Karan | O14: =SUMIF($C$3:$C$52,$N14,$K$3:$K$53) -> 58000 | P14: =AVERAGEIF($C$3:$C$52,N14,$K$3:$K$53) -> 58000
A15: 1013 | B15: 46241 | C15: Simran | D15: Kanpur | E15: Monitor | F15: Electronics | G15: 3 | H15: 13500 | I15: UPI | J15: Priya | K15: =G15*H15 -> 40500 | L15: {=_xlfn.IFS(K15>=100000,"Great Sale",K15>=50000,"Good Sale",K15>=30,"Avg Sale",K15<=10000,"Poor Sale")} -> Avg Sale | N15: Simran | O15: =SUMIF($C$3:$C$52,$N15,$K$3:$K$53) -> 40500 | P15: =AVERAGEIF($C$3:$C$52,N15,$K$3:$K$53) -> 40500
A16: 1014 | B16: 46241 | C16: Aditya | D16: Agra | E16: Headphones | F16: Accessories | G16: 4 | H16: 2200 | I16: Cash | J16: Neha | K16: =G16*H16 -> 8800 | L16: {=_xlfn.IFS(K16>=100000,"Great Sale",K16>=50000,"Good Sale",K16>=30,"Avg Sale",K16<=10000,"Poor Sale")} -> Avg Sale | N16: Aditya | O16: =SUMIF($C$3:$C$52,$N16,$K$3:$K$53) -> 8800 | P16: =AVERAGEIF($C$3:$C$52,N16,$K$3:$K$53) -> 8800
... A43: 1041 | B43: 46255 | C43: Vivek | D43: Lucknow | E43: Printer | F43: Electronics | G43: 1 | H43: 9500 | I43: Card | J43: Priya | K43: =G43*H43 -> 9500 | L43: {=_xlfn.IFS(K43>=100000,"Great Sale",K43>=50000,"Good Sale",K43>=30,"Avg Sale",K43<=10000,"Poor Sale")} -> Avg Sale | N43: Sonam | O43: =SUMIF($C$3:$C$52,$N43,$K$3:$K$53) -> 10800 | P43: =AVERAGEIF($C$3:$C$52,N43,$K$3:$K$53) -> 10800
A44: 1042 | B44: 46255 | C44: Monika | D44: Delhi | E44: Headphones | F44: Accessories | G44: 5 | H44: 2400 | I44: Cash | J44: Neha | K44: =G44*H44 -> 12000 | L44: {=_xlfn.IFS(K44>=100000,"Great Sale",K44>=50000,"Good Sale",K44>=30,"Avg Sale",K44<=10000,"Poor Sale")} -> Avg Sale | O44: =SUM(O5:O43) -> 1578400
A45: 1043 | B45: 46256 | C45: Tarun | D45: Kanpur | E45: Smartphone | F45: Electronics | G45: 2 | H45: 26000 | I45: UPI | J45: Rohit | K45: =G45*H45 -> 52000 | L45: {=_xlfn.IFS(K45>=100000,"Great Sale",K45>=50000,"Good Sale",K45>=30,"Avg Sale",K45<=10000,"Poor Sale")} -> Good Sale
A46: 1044 | B46: 46256 | C46: Ritu | D46: Agra | E46: Keyboard | F46: Accessories | G46: 4 | H46: 1250 | I46: Card | J46: Amit | K46: =G46*H46 -> 5000 | L46: {=_xlfn.IFS(K46>=100000,"Great Sale",K46>=50000,"Good Sale",K46>=30,"Avg Sale",K46<=10000,"Poor Sale")} -> Avg Sale
A47: 1045 | B47: 46257 | C47: Gaurav | D47: Jaipur | E47: Mouse | F47: Accessories | G47: 3 | H47: 950 | I47: UPI | J47: Priya | K47: =G47*H47 -> 2850 | L47: {=_xlfn.IFS(K47>=100000,"Great Sale",K47>=50000,"Good Sale",K47>=30,"Avg Sale",K47<=10000,"Poor Sale")} -> Avg Sale
A48: 1046 | B48: 46257 | C48: Kavita | D48: Lucknow | E48: Laptop | F48: Electronics | G48: 2 | H48: 59000 | I48: Cash | J48: Neha | K48: =G48*H48 -> 118000 | L48: {=_xlfn.IFS(K48>=100000,"Great Sale",K48>=50000,"Good Sale",K48>=30,"Avg Sale",K48<=10000,"Poor Sale")} -> Great Sale
A49: 1047 | B49: 46258 | C49: Vikas | D49: Delhi | E49: Monitor | F49: Electronics | G49: 3 | H49: 14000 | I49: Card | J49: Rohit | K49: =G49*H49 -> 42000 | L49: {=_xlfn.IFS(K49>=100000,"Great Sale",K49>=50000,"Good Sale",K49>=30,"Avg Sale",K49<=10000,"Poor Sale")} -> Avg Sale
A50: 1048 | B50: 46258 | C50: Payal | D50: Kanpur | E50: Printer | F50: Electronics | G50: 2 | H50: 9200 | I50: UPI | J50: Amit | K50: =G50*H50 -> 18400 | L50: {=_xlfn.IFS(K50>=100000,"Great Sale",K50>=50000,"Good Sale",K50>=30,"Avg Sale",K50<=10000,"Poor Sale")} -> Avg Sale
A51: 1049 | B51: 46259 | C51: Nitin | D51: Agra | E51: Smartphone | F51: Electronics | G51: 3 | H51: 20000 | I51: Card | J51: Priya | K51: =G51*H51 -> 60000 | L51: {=_xlfn.IFS(K51>=100000,"Great Sale",K51>=50000,"Good Sale",K51>=30,"Avg Sale",K51<=10000,"Poor Sale")} -> Good Sale
A52: 1050 | B52: 46259 | C52: Sonam | D52: Jaipur | E52: Headphones | F52: Accessories | G52: 4 | H52: 2700 | I52: Cash | J52: Neha | K52: =G52*H52 -> 10800 | L52: {=_xlfn.IFS(K52>=100000,"Great Sale",K52>=50000,"Good Sale",K52>=30,"Avg Sale",K52<=10000,"Poor Sale")} -> Avg Sale
K53: =SUBTOTAL(9,K2:K52) -> 1578400 | L53: {=_xlfn.IFS(K53>=100000,"Great Sale",K53>=50000,"Good Sale",K53>=30,"Avg Sale",K53<=10000,"Poor Sale")} -> Great Sale

Sheet Lookup , VLookup , Index
A1: VLOOKUP
A2: OrderID | B2: Date | C2: Customer | D2: City | E2: Quantity
A3: 1001 | B3: 46235 | C3: Rahul | D3: =VLOOKUP(A3,'Logical formula'!A3:D14,4,FALSE) -> Lucknow | E3: =VLOOKUP(A3,'Logical formula'!A3:$L$14,MATCH('Lookup , VLookup , Index'!$E$2,'Logical formula'!$A$2:$L$2,0)) -> 2
A4: 1002 | B4: 46235 | C4: Priya | D4: =VLOOKUP(A4,'Logical formula'!A4:D15,4,FALSE) -> Kanpur | E4: =VLOOKUP(A4,'Logical formula'!A4:$L$14,MATCH('Lookup , VLookup , Index'!$E$2,'Logical formula'!$A$2:$L$2,0)) -> 3
A5: 1003 | B5: 46236 | C5: Ankit | D5: =VLOOKUP(A5,'Logical formula'!A5:D16,4,FALSE) -> Delhi | E5: =VLOOKUP(A5,'Logical formula'!A5:$L$14,MATCH('Lookup , VLookup , Index'!$E$2,'Logical formula'!$A$2:$L$2,0)) -> 5 | H5: INDEX AND MATCH
A6: 1004 | B6: 46236 | C6: Sneha | D6: =VLOOKUP(A6,'Logical formula'!A6:D17,4,FALSE) -> Lucknow | E6: =VLOOKUP(A6,'Logical formula'!A6:$L$14,MATCH('Lookup , VLookup , Index'!$E$2,'Logical formula'!$A$2:$L$2,0)) -> 4 | H6: OrderID | I6: Customer
A7: 1005 | B7: 46237 | C7: Vivek | D7: =VLOOKUP(A7,'Logical formula'!A7:D18,4,FALSE) -> Jaipur | E7: =VLOOKUP(A7,'Logical formula'!A7:$L$14,MATCH('Lookup , VLookup , Index'!$E$2,'Logical formula'!$A$2:$L$2,0)) -> 2 | H7: 1001 | I7: =INDEX($A$3:$E$14,MATCH(H7,$A$3:$A$14,0),MATCH($I$6,$A$2:$E$2,0)) -> Rahul
A8: 1006 | B8: 46237 | C8: Pooja | D8: =VLOOKUP(A8,'Logical formula'!A8:D19,4,FALSE) -> Delhi | E8: =VLOOKUP(A8,'Logical formula'!A8:$L$14,MATCH('Lookup , VLookup , Index'!$E$2,'Logical formula'!$A$2:$L$2,0)) -> 2 | H8: 1002 | I8: =INDEX($A$3:$E$14,MATCH(H8,$A$3:$A$14,0),MATCH($I$6,$A$2:$E$2,0)) -> Priya
A9: 1007 | B9: 46238 | C9: Kavita | D9: =VLOOKUP(A9,'Logical formula'!A9:D20,4,FALSE) -> Kanpur | E9: =VLOOKUP(A9,'Logical formula'!A9:$L$14,MATCH('Lookup , VLookup , Index'!$E$2,'Logical formula'!$A$2:$L$2,0)) -> 1 | H9: 1003 | I9: =INDEX($A$3:$E$14,MATCH(H9,$A$3:$A$14,0),MATCH($I$6,$A$2:$E$2,0)) -> Ankit
A10: 1008 | B10: 46238 | C10: Kavita | D10: =VLOOKUP(A10,'Logical formula'!A10:D21,4,FALSE) -> Lucknow | E10: =VLOOKUP(A10,'Logical formula'!A10:$L$14,MATCH('Lookup , VLookup , Index'!$E$2,'Logical formula'!$A$2:$L$2,0)) -> 2 | H10: 1006 | I10: =INDEX($A$3:$E$14,MATCH(H10,$A$3:$A$14,0),MATCH($I$6,$A$2:$E$2,0)) -> Pooja
A11: 1009 | B11: 46239 | C11: Riya | D11: =VLOOKUP(A11,'Logical formula'!A11:D22,4,FALSE) -> Agra | E11: =VLOOKUP(A11,'Logical formula'!A11:$L$14,MATCH('Lookup , VLookup , Index'!$E$2,'Logical formula'!$A$2:$L$2,0)) -> 2 | H11: 1005 | I11: =INDEX($A$3:$E$14,MATCH(H11,$A$3:$A$14,0),MATCH($I$6,$A$2:$E$2,0)) -> Vivek
A12: 1010 | B12: 46239 | C12: Ankit | D12: =VLOOKUP(A12,'Logical formula'!A12:D23,4,FALSE) -> Jaipur | E12: =VLOOKUP(A12,'Logical formula'!A12:$L$14,MATCH('Lookup , VLookup , Index'!$E$2,'Logical formula'!$A$2:$L$2,0)) -> 3
A13: 1011 | B13: 46240 | C13: Nisha | D13: =VLOOKUP(A13,'Logical formula'!A13:D24,4,FALSE) -> Lucknow | E13: =VLOOKUP(A13,'Logical formula'!A13:$L$14,MATCH('Lookup , VLookup , Index'!$E$2,'Logical formula'!$A$2:$L$2,0)) -> 6
A14: 1012 | B14: 46240 | C14: Karan | D14: =VLOOKUP(A14,'Logical formula'!A14:D25,4,FALSE) -> Delhi | E14: =VLOOKUP(A14,'Logical formula'!A14:$L$14,MATCH('Lookup , VLookup , Index'!$E$2,'Logical formula'!$A$2:$L$2,0)) -> 1
